<?xml version="1.0" encoding="UTF-8"?>
<testng-results skipped="0" failed="1" ignored="0" total="1" passed="0">
  <reporter-output>
  </reporter-output>
  <suite name="Default suite" duration-ms="2647" started-at="2020-01-27T16:09:44 EST" finished-at="2020-01-27T16:09:46 EST">
    <groups>
    </groups>
    <test name="Default test" duration-ms="2647" started-at="2020-01-27T16:09:44 EST" finished-at="2020-01-27T16:09:46 EST">
      <class name="restassuredTest.Demo4_DELETE_request">
        <test-method status="PASS" signature="putData()[pri:0, instance:restassuredTest.Demo4_DELETE_request@2d6eabae]" name="putData" is-config="true" duration-ms="436" started-at="2020-01-27T16:09:44 EST" finished-at="2020-01-27T16:09:44 EST">
          <reporter-output>
          </reporter-output>
        </test-method> <!-- putData -->
        <test-method status="FAIL" signature="testDelete()[pri:0, instance:restassuredTest.Demo4_DELETE_request@2d6eabae]" name="testDelete" duration-ms="2167" started-at="2020-01-27T16:09:44 EST" finished-at="2020-01-27T16:09:46 EST">
          <exception class="java.lang.AssertionError">
            <message>
              <![CDATA[expected [iterable containing ["successfully! deleted Records"]] but found [{"status":"failed","message":"Error! Not able to delete record"}]]]>
            </message>
            <full-stacktrace>
              <![CDATA[java.lang.AssertionError: expected [iterable containing ["successfully! deleted Records"]] but found [{"status":"failed","message":"Error! Not able to delete record"}]
at org.testng.Assert.fail(Assert.java:97)
at org.testng.Assert.assertEqualsImpl(Assert.java:136)
at org.testng.Assert.assertEquals(Assert.java:118)
at org.testng.Assert.assertEquals(Assert.java:563)
at restassuredTest.Demo4_DELETE_request.testDelete(Demo4_DELETE_request.java:52)
at sun.reflect.NativeMethodAccessorImpl.invoke0(Native Method)
at sun.reflect.NativeMethodAccessorImpl.invoke(NativeMethodAccessorImpl.java:62)
at sun.reflect.DelegatingMethodAccessorImpl.invoke(DelegatingMethodAccessorImpl.java:43)
at java.lang.reflect.Method.invoke(Method.java:498)
at org.testng.internal.MethodInvocationHelper.invokeMethod(MethodInvocationHelper.java:134)
at org.testng.internal.TestInvoker.invokeMethod(TestInvoker.java:597)
at org.testng.internal.TestInvoker.invokeTestMethod(TestInvoker.java:173)
at org.testng.internal.MethodRunner.runInSequence(MethodRunner.java:46)
at org.testng.internal.TestInvoker$MethodInvocationAgent.invoke(TestInvoker.java:816)
at org.testng.internal.TestInvoker.invokeTestMethods(TestInvoker.java:146)
at org.testng.internal.TestMethodWorker.invokeTestMethods(TestMethodWorker.java:146)
at org.testng.internal.TestMethodWorker.run(TestMethodWorker.java:128)
at java.util.ArrayList.forEach(ArrayList.java:1249)
at org.testng.TestRunner.privateRun(TestRunner.java:766)
at org.testng.TestRunner.run(TestRunner.java:587)
at org.testng.SuiteRunner.runTest(SuiteRunner.java:384)
at org.testng.SuiteRunner.runSequentially(SuiteRunner.java:378)
at org.testng.SuiteRunner.privateRun(SuiteRunner.java:337)
at org.testng.SuiteRunner.run(SuiteRunner.java:286)
at org.testng.SuiteRunnerWorker.runSuite(SuiteRunnerWorker.java:53)
at org.testng.SuiteRunnerWorker.run(SuiteRunnerWorker.java:96)
at org.testng.TestNG.runSuitesSequentially(TestNG.java:1187)
at org.testng.TestNG.runSuitesLocally(TestNG.java:1109)
at org.testng.TestNG.runSuites(TestNG.java:1039)
at org.testng.TestNG.run(TestNG.java:1007)
at org.testng.remote.AbstractRemoteTestNG.run(AbstractRemoteTestNG.java:115)
at org.testng.remote.RemoteTestNG.initAndRun(RemoteTestNG.java:251)
at org.testng.remote.RemoteTestNG.main(RemoteTestNG.java:77)
]]>
            </full-stacktrace>
          </exception> <!-- java.lang.AssertionError -->
          <reporter-output>
          </reporter-output>
        </test-method> <!-- testDelete -->
      </class> <!-- restassuredTest.Demo4_DELETE_request -->
    </test> <!-- Default test -->
  </suite> <!-- Default suite -->
</testng-results>
